Workbook

Sheet Daftar & Kamus Data
B2: DATABASE OPERASIONAL & TELEMETRI SCADA
B3: PT. Pionir Nusantara Sukses - Bulk Mixing & Drying Plant (20 Ton/Jam)
B5: No | C5: Nama Tabel | D5: Kategori Entitas | E5: Jumlah Kolom | F5: Jumlah Data | G5: Deskripsi Fungsional
B6: 1 | C6: master_bahan_baku | D6: Master Reference | E6: 10 | F6: 10 | G6: Katalog bahan baku, densitas ruah (Bulk Density), formulasi (80:15:5), harga beli & safety stock.
B7: 2 | C7: master_fasilitas_storage | D7: Master Reference | E7: 10 | F7: 10 | G7: Spesifikasi fisik stockpile (134.4T & 120.96T), tangki aditif, rotary dryer, dan Bin Silo 72 m³.
B8: 3 | C8: log_logistik_inbound | D8: Transactional Fact | E8: 12 | F8: 10 | G8: Pencatatan ritase truk tronton bahan mentah masuk (@ 30T), jembatan timbang, dan alokasi bay stockpile.
B9: 4 | C9: log_logistik_outbound | D9: Transactional Fact | E9: 12 | F9: 10 | G9: Pencatatan pengiriman truk produk jadi dari Bin Silo (ritme 2 jam), surat jalan, dan buffer level.
B10: 5 | C10: telemetri_produksi_scada | D10: Time-Series Telemetry | E10: 12 | F10: 10 | G10: Data sensor SCADA per jam: Tonase output (target 20 T/h), suhu rotary dryer (°C), MMBTU gas, dan kWh PLN.
B11: 6 | C11: biaya_siklus_hpp | D11: Financial Analytics | E11: 14 | F11: 10 | G11: Kalkulasi biaya per shift: Bahan baku, komparasi energi PGN vs CNG, listrik, solar forklift, SDM & HPP/Ton.
B12: 7 | C12: insiden_downtime_bottleneck | D12: Incident & Loss Fact | E12: 12 | F12: 10 | G12: Pencatatan kejadian bottleneck (Truk Macet, Mesin Rusak, Lampu Mati), biaya SDM menganggur, penalti burner & lost margin.
B13: 8 | C13: rekap_kinerja_eksekutif | D13: Executive KPI Summary | E13: 13 | F13: 10 | G13: KPI harian Direksi: Output kumulatif, capaian target shift (140T), efisiensi PGN bulanan, kerugian harian, dan progres BEP Capex Rp 5.15 M.
B14: 9 | C14: simulasi_skenario_demand_range | D14: Scenario Simulation | E14: 18 | F14: 6 | G14: Model simulasi dinamis rentang output multi-level (80T - 420T/hari), 6 skenario lonjakan komersial & tender masif pemerintah, analisis logistik armada truk (@30T), HPP, omzet, laba kotor, working capital cash flow (TOP 30/60/90 hari), 8 dinamika industri lokal Indonesia, dan timeline jadwal dispatch per jam.
B16: PARAMETER BENCHMARK TEKNIS & FINANSIAL PABRIK (EXCEL AUDIT):
B17: Kapasitas Desain Pabrik | C17: 20.00 Ton / Jam (140.00 Ton per shift 7 jam)
B18: Target Bulanan | C18: 3,500.00 Ton (25 Hari Kerja) s.d. 4,200.00 Ton (30 Hari Kerja)
B19: Komposisi Formulasi | C19: 80% Bentonite (BJ 0.8) | 15% Calsium Carbonate (BJ 2.8) | 5% Soda Ash (BJ 1.13)
B20: Daya Tampung Stockpile 1 (Bentonite) | C20: 134.40 Ton (Habis dalam 8.40 Jam Operasi Penuh jika pasokan terputus)
B21: Daya Tampung Stockpile 2 (Calsium) | C21: 120.96 Ton (Habis dalam 40.32 Jam Operasi Penuh)
B22: Kapasitas Bin Silo Produk Akhir | C22: 72.00 m³ (65.58 s.d. 86.40 Ton) -> Buffer holding time: 3.28 s.d. 4.32 Jam
B23: Ritme Pengiriman Produk Jadi | C23: Wajib loading truk (@ 30 Ton) setiap 2 jam sekali agar Silo tidak meluap
B24: Disparitas Energi PGN vs CNG | C24: PGN $13.00/MMBTU (Rp 79,930/t) vs CNG $15.15/MMBTU (Rp 95,301/t) -> Hemat Rp 53.8 Juta/Bulan
B25: Biaya Investasi Awal (Capex) | C25: Rp 5,150,000,000 (Target Balik Modal BEP: 4.7 s.d. 12.3 Bulan)
B26: Beban SDM Shift Menganggur | C26: Rp 382,143 per jam downtime (Alokasi 10 personil operasional = Rp 66,875,000/bulan)

Sheet master_bahan_baku
A1: TABEL: MASTER_BAHAN_BAKU
A2: id_bahan | B2: nama_bahan | C2: kategori | D2: bulk_density_t_m3 | E2: persentase_formula_pct | F2: harga_satuan_rp_kg | G2: satuan_standar | H2: safety_stock_ton | I2: lead_time_hari | J2: supplier_utama
A3: RM-BEN-01 | B3: Bentonite Clay Curah | C3: Bahan Baku Utama | D3: 0.8 | E3: 80 | F3: 3650 | G3: Kg | H3: 50 | I3: 1 | J3: PT. Indo Mineral Resources
A4: RM-CAL-02 | B4: Calsium Carbonate (CaCO3) | C4: Bahan Baku Utama | D4: 2.8 | E4: 15 | F4: 2750 | G4: Kg | H4: 30 | I4: 3 | J4: PT. Padalarang Kalsium Nusantara
A5: RM-SDA-03 | B5: Soda Ash Dense (Na2CO3) | C5: Aditif Aktivasi | D5: 1.13 | E5: 5 | F5: 5000 | G5: Kg | H5: 10 | I5: 7 | J5: PT. Solvay Alkali Indonesia
A6: RM-SDAL-04 | B6: Soda Ash Light | C6: Aditif Alternatif | D6: 0.65 | E6: 0 | F6: 5200 | G6: Kg | H6: 5 | I6: 7 | J6: PT. Kimia Aditif Pratama
A7: RM-QCK-05 | B7: Quicklime (CaO Active) | C7: Aditif Stabilizer | D7: 1.05 | E7: 0 | F7: 3100 | G7: Kg | H7: 10 | I7: 4 | J7: PT. Gamping Mas Sejahtera
A8: RM-KAO-06 | B8: Kaolin Powder | C8: Binder Sekunder | D8: 1.2 | E8: 0 | F8: 2900 | G8: Kg | H8: 15 | I8: 5 | J8: PT. Kaolin Bumi Sriwijaya
A9: PK-JMB-07 | B9: Jumbo Bag 1 Ton Polypropylene | C9: Kemasan | D9: 0 | E9: 0 | F9: 85000 | G9: Pcs | H9: 500 | I9: 10 | J9: PT. Polychem Kemas Lestari
A10: PK-PLT-08 | B10: Palet Kayu ISPM 15 Standar | C10: Penyangga | D10: 0 | E10: 0 | F10: 125000 | G10: Pcs | H10: 200 | I10: 14 | J10: PT. Palet Kreasi Mandiri
A11: EN-PGN-09 | B11: Gas Alam Pipa (PGN $13/MMBTU) | C11: Energi Burner | D11: 0 | E11: 0 | F11: 234000 | G11: MMBTU | H11: 1500 | I11: 0 | J11: PT. Perusahaan Gas Negara
A12: EN-CNG-10 | B12: Compressed Natural Gas ($15.15) | C12: Energi Cadangan | D12: 0 | E12: 0 | F12: 279000 | G12: MMBTU | H12: 1500 | I12: 1 | J12: PT. CNG Hilir Utama

Sheet master_fasilitas_storage
A1: TABEL: MASTER_FASILITAS_STORAGE
A2: id_fasilitas | B2: nama_fasilitas | C2: tipe_aset | D2: dimensi_pxlxt_m | E2: volume_m3 | F2: kapasitas_maks_ton | G2: buffer_time_jam | H2: lokasi_plant | I2: daya_listrik_kw | J2: status_operasional
A3: ST-SP-01 | B3: Stockpile 1 (Bentonite Curah) | C3: Stockpile Yard | D3: 18 x 6 x 3 | E3: 324 | F3: 134.4 | G3: 8.4 | H3: Yard Utara (Bay 1) | I3: 0 | J3: Aktif
A4: ST-SP-02 | B4: Stockpile 2 (Calsium Curah) | C4: Stockpile Yard | D4: 6 x 6 x 3 | E4: 108 | F4: 120.96 | G4: 40.32 | H4: Yard Utara (Bay 2) | I4: 0 | J4: Aktif
A5: ST-TK-03 | B5: Tangki Dosing Soda Ash | C5: Dosing Tank | D5: Dia 3 x 4 | E5: 28.26 | F5: 31.93 | G5: 31.93 | H5: Batching Plant Area | I5: 5.5 | J5: Aktif
A6: EQ-FL-01 | B6: Forklift Diesel Komatsu 3 Ton | C6: Transport Unit | D6: 3.5 x 1.2 x 2.1 | E6: 0 | F6: 3 | G6: 0 | H6: Yard ke Hopper | I6: 35 | J6: Aktif
A7: EQ-HP-01 | B7: Hopper & Weight Feeder | C7: Continuous Feeder | D7: 4 x 3 x 3.5 | E7: 30 | F7: 25 | G7: 1.25 | H7: Lantai Feeding | I7: 15 | J7: Aktif
A8: EQ-RD-01 | B8: Rotary Drum Dryer 20 T/h | C8: Reaktor Pengering | D8: 18 x Dia 2.5 | E8: 88.35 | F8: 20 | G8: 1 | H8: Furnace Area | I8: 55 | J8: Aktif
A9: EQ-BN-01 | B9: Dual-Fuel Burner (PGN/CNG) | C9: Pemanas Burner | D9: 2 x 1.5 x 1.5 | E9: 0 | F9: 0 | G9: 0 | H9: Ruang Pembakaran | I9: 7.5 | J9: Aktif
A10: EQ-CV-01 | B10: Conveyor Belt System (1-4) | C10: Belt Conveyor | D10: 45 x 0.8 x 0.5 | E10: 0 | F10: 25 | G10: 0 | H10: Jalur Dryer-Silo | I10: 18.5 | J10: Aktif
A11: ST-SL-01 | B11: Bin Silo Produk Akhir | C11: Storage Silo | D11: Dia 4 x 6 | E11: 72 | F11: 86.4 | G11: 4.32 | H11: Outbound Loading Bay | I11: 11 | J11: Aktif
A12: EQ-WB-01 | B12: Jembatan Timbang Truk 60 Ton | C12: Timbangan | D12: 16 x 3.2 x 0.5 | E12: 0 | F12: 60 | G12: 0 | H12: Pintu Gerbang Utama | I12: 3 | J12: Aktif

Sheet log_logistik_inbound
A1: TABEL: LOG_LOGISTIK_INBOUND
A2: id_inbound | B2: no_surat_jalan | C2: id_bahan | D2: no_polisi_truk | E2: nama_transporter | F2: waktu_timbang_masuk | G2: waktu_selesai_bongkar | H2: berat_bruto_kg | I2: berat_tara_kg | J2: berat_netto_ton | K2: id_fasilitas_tujuan | L2: status_qc
A3: INB-261001-01 | B3: SJ-IMR-88901 | C3: RM-BEN-01 | D3: B 9421 UYT | E3: PT. Lintas Logistik Prima | F3: 2026-10-01 06:15:00 | G3: 2026-10-01 07:05:00 | H3: 44250 | I3: 14200 | J3: 30.05 | K3: ST-SP-01 | L3: PASSED
A4: INB-261001-02 | B4: SJ-IMR-88902 | C4: RM-BEN-01 | D4: B 9112 PKO | E4: PT. Lintas Logistik Prima | F4: 2026-10-01 07:45:00 | G4: 2026-10-01 08:30:00 | H4: 44180 | I4: 14150 | J4: 30.03 | K4: ST-SP-01 | L4: PASSED
A5: INB-261001-03 | B5: SJ-PKN-45120 | C5: RM-CAL-02 | D5: D 9833 KLA | E5: CV. Sumber Kalsium Abadi | F5: 2026-10-01 08:30:00 | G5: 2026-10-01 09:20:00 | H5: 45100 | I5: 15020 | J5: 30.08 | K5: ST-SP-02 | L5: PASSED
A6: INB-261001-04 | B6: SJ-IMR-88903 | C6: RM-BEN-01 | D6: B 9554 TYA | E6: PT. Lintas Logistik Prima | F6: 2026-10-01 09:40:00 | G6: 2026-10-01 10:25:00 | H6: 44320 | I6: 14310 | J6: 30.01 | K6: ST-SP-01 | L6: PASSED
A7: INB-261001-05 | B7: SJ-SOL-11029 | C7: RM-SDA-03 | D7: L 8120 UVY | E7: PT. Samudera Kimia Trans | F7: 2026-10-01 10:15:00 | G7: 2026-10-01 11:00:00 | H7: 28500 | I7: 8500 | J7: 20 | K7: ST-TK-03 | L7: PASSED
A8: INB-261001-06 | B8: SJ-IMR-88904 | C8: RM-BEN-01 | D8: B 9230 ZXT | E8: PT. Lintas Logistik Prima | F8: 2026-10-01 11:30:00 | G8: 2026-10-01 12:20:00 | H8: 44290 | I8: 14240 | J8: 30.05 | K8: ST-SP-01 | L8: PASSED
A9: INB-261001-07 | B9: SJ-IMR-88905 | C9: RM-BEN-01 | D9: B 9771 MNQ | E9: PT. Lintas Logistik Prima | F9: 2026-10-01 13:15:00 | G9: 2026-10-01 14:05:00 | H9: 44150 | I9: 14190 | J9: 29.96 | K9: ST-SP-01 | L9: PASSED
A10: INB-261002-01 | B10: SJ-IMR-88910 | C10: RM-BEN-01 | D10: B 9421 UYT | E10: PT. Lintas Logistik Prima | F10: 2026-10-02 06:20:00 | G10: 2026-10-02 07:10:00 | H10: 44300 | I10: 14220 | J10: 30.08 | K10: ST-SP-01 | L10: PASSED
A11: INB-261002-02 | B11: SJ-IMR-88911 | C11: RM-BEN-01 | D11: B 9112 PKO | E11: PT. Lintas Logistik Prima | F11: 2026-10-02 07:50:00 | G11: 2026-10-02 08:35:00 | H11: 44210 | I11: 14180 | J11: 30.03 | K11: ST-SP-01 | L11: PASSED
A12: INB-261002-03 | B12: SJ-IMR-88912 | C12: RM-BEN-01 | D12: B 9554 TYA | E12: PT. Lintas Logistik Prima | F12: 2026-10-02 09:30:00 | G12: 2026-10-02 10:15:00 | H12: 44190 | I12: 14200 | J12: 29.99 | K12: ST-SP-01 | L12: PASSED

Sheet log_logistik_outbound
A1: TABEL: LOG_LOGISTIK_OUTBOUND
A2: id_outbound | B2: no_surat_jalan_out | C2: nama_customer | D2: no_polisi_truk | E2: id_fasilitas_asal | F2: waktu_mulai_loading | G2: waktu_selesai_dispatch | H2: level_silo_sebelum_ton | I2: tonase_keluar_ton | J2: level_silo_sesudah_ton | K2: tipe_pengiriman | L2: status_pengiriman
A3: OUT-261001-01 | B3: SJ-OUT-1001 | C3: PT. Semen Nusantara Utama | D3: L 9921 AB | E3: ST-SL-01 | F3: 2026-10-01 08:30:00 | G3: 2026-10-01 09:05:00 | H3: 40 | I3: 30 | J3: 10 | K3: Bulk Silo Truck | L3: DISPATCHED
A4: OUT-261001-02 | B4: SJ-OUT-1002 | C4: PT. Pengecoran Logam Perkasa | D4: B 9340 TYU | E4: ST-SL-01 | F4: 2026-10-01 10:30:00 | G4: 2026-10-01 11:00:00 | H4: 50 | I4: 30 | J4: 20 | K4: Bulk Silo Truck | L4: DISPATCHED
A5: OUT-261001-03 | B5: SJ-OUT-1003 | C5: PT. Geoteknik Fondasi Mandiri | D5: W 8820 PO | E5: ST-SL-01 | F5: 2026-10-01 12:30:00 | G5: 2026-10-01 13:05:00 | H5: 60 | I5: 30 | J5: 30 | K5: Bulk Silo Truck | L5: DISPATCHED
A6: OUT-261001-04 | B6: SJ-OUT-1004 | C6: PT. Pengecoran Logam Perkasa | D6: N 9122 JK | E6: ST-SL-01 | F6: 2026-10-01 14:30:00 | G6: 2026-10-01 15:00:00 | H6: 70 | I6: 30 | J6: 40 | K6: Bulk Silo Truck | L6: DISPATCHED
A7: OUT-261001-05 | B7: SJ-OUT-1005 | C7: PT. Semen Nusantara Utama | D7: L 9921 AB | E7: ST-SL-01 | F7: 2026-10-01 16:00:00 | G7: 2026-10-01 16:30:00 | H7: 50 | I7: 20 | J7: 30 | K7: Bulk Silo Truck | L7: DISPATCHED
A8: OUT-261002-01 | B8: SJ-OUT-1006 | C8: PT. Geoteknik Fondasi Mandiri | D8: W 8820 PO | E8: ST-SL-01 | F8: 2026-10-02 08:30:00 | G8: 2026-10-02 09:00:00 | H8: 45 | I8: 30 | J8: 15 | K8: Bulk Silo Truck | L8: DISPATCHED
A9: OUT-261002-02 | B9: SJ-OUT-1007 | C9: PT. Semen Nusantara Utama | D9: L 9921 AB | E9: ST-SL-01 | F9: 2026-10-02 10:30:00 | G9: 2026-10-02 11:05:00 | H9: 55 | I9: 30 | J9: 25 | K9: Bulk Silo Truck | L9: DISPATCHED
A10: OUT-261002-03 | B10: SJ-OUT-1008 | C10: PT. Pengecoran Logam Perkasa | D10: B 9340 TYU | E10: ST-SL-01 | F10: 2026-10-02 12:30:00 | G10: 2026-10-02 13:00:00 | H10: 65 | I10: 30 | J10: 35 | K10: Bulk Silo Truck | L10: DISPATCHED
A11: OUT-261002-04 | B11: SJ-OUT-1009 | C11: PT. Agro Kimia Perkasa | D11: AG 8221 UI | E11: ST-SL-01 | F11: 2026-10-02 14:30:00 | G11: 2026-10-02 15:10:00 | H11: 75 | I11: 30 | J11: 45 | K11: Jumbo Bag 1T | L11: DISPATCHED
A12: OUT-261002-05 | B12: SJ-OUT-1010 | C12: PT. Semen Nusantara Utama | D12: N 9122 JK | E12: ST-SL-01 | F12: 2026-10-02 16:15:00 | G12: 2026-10-02 16:45:00 | H12: 55 | I12: 20 | J12: 35 | K12: Bulk Silo Truck | L12: DISPATCHED

Sheet telemetri_produksi_scada
A1: TABEL: TELEMETRI_PRODUKSI_SCADA
A2: id_telemetri | B2: timestamp_record | C2: shift_kerja | D2: target_kapasitas_ton_jam | E2: aktual_output_ton_jam | F2: temp_rotary_dryer_c | G2: burner_flame_intensity_pct | H2: konsumsi_gas_mmbtu_jam | I2: konsumsi_listrik_kwh | J2: conveyor_speed_m_s | K2: vibrating_screen_status | L2: kondisi_scada
A3: SC-261001-07 | B3: 2026-10-01 07:00:00 | C3: Shift 1 | D3: 20 | E3: 19.8 | F3: 218.5 | G3: 92 | H3: 6.732 | I3: 98.4 | J3: 1.2 | K3: NORMAL | L3: RUNNING
A4: SC-261001-08 | B4: 2026-10-01 08:00:00 | C4: Shift 1 | D4: 20 | E4: 20.1 | F4: 222 | G4: 94.5 | H4: 6.834 | I4: 100.2 | J4: 1.25 | K4: NORMAL | L4: RUNNING
A5: SC-261001-09 | B5: 2026-10-01 09:00:00 | C5: Shift 1 | D5: 20 | E5: 20.05 | F5: 220.8 | G5: 93.8 | H5: 6.817 | I5: 99.8 | J5: 1.25 | K5: NORMAL | L5: RUNNING
A6: SC-261001-10 | B6: 2026-10-01 10:00:00 | C6: Shift 1 | D6: 20 | E6: 20.2 | F6: 223.1 | G6: 95 | H6: 6.868 | I6: 101.5 | J6: 1.25 | K6: NORMAL | L6: RUNNING
A7: SC-261001-11 | B7: 2026-10-01 11:00:00 | C7: Shift 1 | D7: 20 | E7: 19.95 | F7: 221.4 | G7: 93.2 | H7: 6.783 | I7: 99.1 | J7: 1.2 | K7: NORMAL | L7: RUNNING
A8: SC-261001-12 | B8: 2026-10-01 12:00:00 | C8: Shift 1 | D8: 20 | E8: 19.7 | F8: 219 | G8: 91.5 | H8: 6.698 | I8: 97.6 | J8: 1.2 | K8: NORMAL | L8: RUNNING
A9: SC-261001-13 | B9: 2026-10-01 13:00:00 | C9: Shift 1 | D9: 20 | E9: 20.2 | F9: 222.5 | G9: 94 | H9: 6.868 | I9: 100.9 | J9: 1.25 | K9: NORMAL | L9: RUNNING
A10: SC-261002-07 | B10: 2026-10-02 07:00:00 | C10: Shift 1 | D10: 20 | E10: 19.85 | F10: 219.5 | G10: 92.5 | H10: 6.749 | I10: 98.8 | J10: 1.2 | K10: NORMAL | L10: RUNNING
A11: SC-261002-08 | B11: 2026-10-02 08:00:00 | C11: Shift 1 | D11: 20 | E11: 20.15 | F11: 221.8 | G11: 94.2 | H11: 6.851 | I11: 100.5 | J11: 1.25 | K11: NORMAL | L11: RUNNING
A12: SC-261002-09 | B12: 2026-10-02 09:00:00 | C12: Shift 1 | D12: 20 | E12: 12.5 | F12: 195 | G12: 60 | H12: 4.25 | I12: 72.3 | J12: 0.75 | K12: WARNING | L12: BOTTLENECK

Sheet biaya_siklus_hpp
A1: TABEL: BIAYA_SIKLUS_HPP
A2: id_biaya_siklus | B2: tanggal_siklus | C2: shift_kerja | D2: output_tonase_ton | E2: jenis_energi_aktif | F2: biaya_raw_material_rp | G2: biaya_bahan_bakar_rp | H2: biaya_listrik_pln_rp | I2: biaya_forklift_solar_rp | J2: alokasi_sdm_rp | K2: biaya_maintenance_per_ton_rp | L2: total_hpp_per_ton_rp | M2: harga_jual_per_ton_rp | N2: gross_margin_per_ton_rp
A3: CST-261001-01 | B3: 2026-10-01 | C3: Shift 1 | D3: 140 | E3: PGN | F3: 501550000 | G3: 11190200 | H3: 1011220 | I3: 663320 | J3: 2675000 | K3: 139006 | L3: 3582500 | M3: 4350000 | N3: =M3-L3-K3
A4: CST-261002-01 | B4: 2026-10-02 | C4: Shift 1 | D4: 132.5 | E4: PGN | F4: 474681250 | G4: 10590725 | H4: 957048 | I4: 627785 | J4: 2675000 | K4: 139006 | L4: 3582500 | M4: 4350000 | N4: =M4-L4-K4
A5: CST-261003-01 | B5: 2026-10-03 | C5: Shift 1 | D5: 140 | E5: PGN | F5: 501550000 | G5: 11190200 | H5: 1011220 | I5: 663320 | J5: 2675000 | K5: 139006 | L5: 3582500 | M5: 4350000 | N5: =M5-L5-K5
A6: CST-261004-01 | B6: 2026-10-04 | C6: Shift 1 | D6: 140 | E6: CNG | F6: 501550000 | G6: 13342140 | H6: 1011220 | I6: 663320 | J6: 2675000 | K6: 139006 | L6: 3582500 | M6: 4350000 | N6: =M6-L6-K6
A7: CST-261005-01 | B7: 2026-10-05 | C7: Shift 1 | D7: 140 | E7: PGN | F7: 501550000 | G7: 11190200 | H7: 1011220 | I7: 663320 | J7: 2675000 | K7: 139006 | L7: 3582500 | M7: 4350000 | N7: =M7-L7-K7
A8: CST-261006-01 | B8: 2026-10-06 | C8: Shift 1 | D8: 140 | E8: PGN | F8: 501550000 | G8: 11190200 | H8: 1011220 | I8: 663320 | J8: 2675000 | K8: 139006 | L8: 3582500 | M8: 4350000 | N8: =M8-L8-K8
A9: CST-261007-01 | B9: 2026-10-07 | C9: Shift 1 | D9: 140 | E9: PGN | F9: 501550000 | G9: 11190200 | H9: 1011220 | I9: 663320 | J9: 2675000 | K9: 139006 | L9: 3582500 | M9: 4350000 | N9: =M9-L9-K9
A10: CST-261008-01 | B10: 2026-10-08 | C10: Shift 1 | D10: 140 | E10: PGN | F10: 501550000 | G10: 11190200 | H10: 1011220 | I10: 663320 | J10: 2675000 | K10: 139006 | L10: 3582500 | M10: 4350000 | N10: =M10-L10-K10
A11: CST-261009-01 | B11: 2026-10-09 | C11: Shift 1 | D11: 140 | E11: PGN | F11: 501550000 | G11: 11190200 | H11: 1011220 | I11: 663320 | J11: 2675000 | K11: 139006 | L11: 3582500 | M11: 4350000 | N11: =M11-L11-K11
A12: CST-261010-01 | B12: 2026-10-10 | C12: Shift 1 | D12: 140 | E12: PGN | F12: 501550000 | G12: 11190200 | H12: 1011220 | I12: 663320 | J12: 2675000 | K12: 139006 | L12: 3582500 | M12: 4350000 | N12: =M12-L12-K12

Sheet insiden_downtime_bottleneck
A1: TABEL: INSIDEN_DOWNTIME_BOTTLENECK
A2: id_insiden | B2: kategori_bottleneck | C2: deskripsi_kejadian | D2: waktu_mulai | E2: waktu_selesai | F2: durasi_jam | G2: output_hilang_ton | H2: biaya_sdm_menganggur_rp | I2: bahan_bakar_terbuang_rp | J2: kehilangan_laba_margin_rp | K2: total_kerugian_rp | L2: tindakan_perbaikan
A3: DWT-261002-01 | B3: Truk Macet | C3: Keterlambatan Truk Bentonite (Macet Tol Cikampek KM 52) | D3: 2026-10-02 09:15:00 | E3: 2026-10-02 12:45:00 | F3: 3.5 | G3: 70 | H3: 1337500 | I3: =F3*telemetri_produksi_scada!H3*master_bahan_baku!F11 | J3: =G3*biaya_siklus_hpp!N3 | K3: =SUM(H3:J3) | L3: Pengalihan rute armada & koordinasi buffer stockpile
A4: DWT-261003-02 | B4: Mesin Rusak | C4: Bearing Roll Rotary Dryer Overheat (Suhu 245°C) | D4: 2026-10-03 13:00:00 | E4: 2026-10-03 15:00:00 | F4: 2 | G4: 40 | H4: 764286 | I4: =F4*telemetri_produksi_scada!H4*master_bahan_baku!F11 | J4: =G4*biaya_siklus_hpp!N4 | K4: =SUM(H4:J4) | L4: Penggantian bearing darurat & re-greasing suhu tinggi
A5: DWT-261004-01 | B5: Lampu Mati | C5: Pemadaman Gardu Induk PLN (Trip Trafo 125 kVA) | D5: 2026-10-04 10:20:00 | E5: 2026-10-04 12:50:00 | F5: 2.5 | G5: 50 | H5: 955357 | I5: =F5*telemetri_produksi_scada!H5*master_bahan_baku!F11 | J5: =G5*biaya_siklus_hpp!N5 | K5: =SUM(H5:J5) | L5: Sinkronisasi genset darurat & reset panel starter
A6: DWT-261005-01 | B6: Mesin Rusak | C6: Belt Conveyor 2 Robek Terkena Benda Tajam | D6: 2026-10-05 08:30:00 | E6: 2026-10-05 10:00:00 | F6: 1.5 | G6: 30 | H6: 573214 | I6: =F6*telemetri_produksi_scada!H6*master_bahan_baku!F12 | J6: =G6*biaya_siklus_hpp!N6 | K6: =SUM(H6:J6) | L6: Penyambungan belt mechanical joint fast-lock
A7: DWT-261006-01 | B7: Truk Macet | C7: Antrean Timbang Pelabuhan Tanjung Perak Padat | D7: 2026-10-06 14:00:00 | E7: 2026-10-06 15:30:00 | F7: 1.5 | G7: 30 | H7: 573214 | I7: =F7*telemetri_produksi_scada!H7*master_bahan_baku!F11 | J7: =G7*biaya_siklus_hpp!N7 | K7: =SUM(H7:J7) | L7: Dispatch armada cadangan dari depo penyangga
A8: DWT-261007-01 | B8: Mesin Rusak | C8: Sensor Flame Detector Burner PGN Kotor/Error | D8: 2026-10-07 11:15:00 | E8: 2026-10-07 12:00:00 | F8: 0.75 | G8: 15 | H8: 286607 | I8: =F8*telemetri_produksi_scada!H8*master_bahan_baku!F11 | J8: =G8*biaya_siklus_hpp!N8 | K8: =SUM(H8:J8) | L8: Pembersihan probe sensor UV & kalibrasi ulang
A9: DWT-261008-01 | B9: Lampu Mati | C9: Fluktuasi Tegangan PLN Drop (Under-voltage Trip) | D9: 2026-10-08 09:00:00 | E9: 2026-10-08 10:00:00 | F9: 1 | G9: 20 | H9: 382143 | I9: =F9*telemetri_produksi_scada!H9*master_bahan_baku!F11 | J9: =G9*biaya_siklus_hpp!N9 | K9: =SUM(H9:J9) | L9: Penyetelan relai proteksi voltage stabilizer
A10: DWT-261009-01 | B10: Truk Macet | C10: Truk Pengangkut Silo Rusak di Gerbang Timbang | D10: 2026-10-09 13:30:00 | E10: 2026-10-09 15:30:00 | F10: 2 | G10: 40 | H10: 764286 | I10: =F10*telemetri_produksi_scada!H10*master_bahan_baku!F11 | J10: =G10*biaya_siklus_hpp!N10 | K10: =SUM(H10:J10) | L10: Penarikan kendaraan derek & buka jalur darurat
A11: DWT-261010-01 | B11: Mesin Rusak | C11: Vibrating Screen Choked (Penyumbatan Gumpalan) | D11: 2026-10-10 10:45:00 | E11: 2026-10-10 11:45:00 | F11: 1 | G11: 20 | H11: 382143 | I11: =F11*telemetri_produksi_scada!H11*master_bahan_baku!F11 | J11: =G11*biaya_siklus_hpp!N11 | K11: =SUM(H11:J11) | L11: Pembersihan wire mesh screen & kontrol kadar air
A12: DWT-261011-01 | B12: Truk Macet | C12: Kendala Administrasi DO Soda Ash di Gudang Transit | D12: 2026-10-11 08:00:00 | E12: 2026-10-11 10:30:00 | F12: 2.5 | G12: 50 | H12: 955357 | I12: =F12*telemetri_produksi_scada!H12*master_bahan_baku!F11 | J12: =G12*biaya_siklus_hpp!N12 | K12: =SUM(H12:J12) | L12: Percepatan kliring digital & pinjam buffer lokal

Sheet rekap_kinerja_eksekutif
A1: TABEL: REKAP_KINERJA_EKSEKUTIF
A2: id_rekap_kpi | B2: tanggal | C2: jam_operasional_efektif | D2: total_output_produksi_ton | E2: target_harian_ton | F2: capaian_target_pct | G2: total_rit_inbound | H2: total_rit_outbound | I2: efisiensi_pgn_vs_cng_rp | J2: kerugian_downtime_hari_ini_rp | K2: laba_kotor_harian_rp | L2: kumulatif_laba_bersih_rp | M2: progres_bep_capex_pct
A3: KPI-261001 | B3: 2026-10-01 | C3: 7 | D3: 140 | E3: 140 | F3: 100 | G3: 7 | H3: 5 | I3: 2151940 | J3: 0 | K3: 90355300 | L3: 45177650 | M3: 0.88
A4: KPI-261002 | B4: 2026-10-02 | C4: 6.63 | D4: 132.5 | E4: 140 | F4: 94.64 | G4: 6 | H4: 5 | I4: 2036657 | J4: 46515150 | K4: 85516368 | L4: 87935834 | M4: 1.71
A5: KPI-261003 | B5: 2026-10-03 | C5: 7 | D5: 140 | E5: 140 | F5: 100 | G5: 7 | H5: 5 | I5: 2151940 | J5: 43795476 | K5: 90355300 | L5: 133113484 | M5: 2.58
A6: KPI-261004 | B6: 2026-10-04 | C6: 7 | D6: 140 | E6: 140 | F6: 100 | G6: 6 | H6: 5 | I6: 0 | J6: 53725107 | K6: 87989160 | L6: 177108064 | M6: 3.44
A7: KPI-261005 | B7: 2026-10-05 | C7: 7 | D7: 140 | E7: 140 | F7: 100 | G7: 7 | H7: 5 | I7: 2151940 | J7: 37150454 | K7: 90355300 | L7: 222285714 | M7: 4.32
A8: KPI-261006 | B8: 2026-10-06 | C8: 7 | D8: 140 | E8: 140 | F8: 100 | G8: 7 | H8: 5 | I8: 2151940 | J8: 19935064 | K8: 90355300 | L8: 267463364 | M8: 5.19
A9: KPI-261007 | B9: 2026-10-07 | C9: 7 | D9: 140 | E9: 140 | F9: 100 | G9: 7 | H9: 5 | I9: 2151940 | J9: 18575227 | K9: 90355300 | L9: 312641014 | M9: 6.07
A10: KPI-261008 | B10: 2026-10-08 | C10: 7 | D10: 140 | E10: 140 | F10: 100 | G10: 7 | H10: 5 | I10: 2151940 | J10: 30505433 | K10: 90355300 | L10: 357818664 | M10: 6.95
A11: KPI-261009 | B11: 2026-10-09 | C11: 7 | D11: 140 | E11: 140 | F11: 100 | G11: 7 | H11: 5 | I11: 2151940 | J11: 26580086 | K11: 90355300 | L11: 402996314 | M11: 7.83
A12: KPI-261010 | B12: 2026-10-10 | C12: 7 | D12: 140 | E12: 140 | F12: 100 | G12: 7 | H12: 5 | I12: 2151940 | J12: 21897738 | K12: 90355300 | L12: 448173964 | M12: 8.7

Sheet simulasi_skenario_demand_range
A1: SIMULASI RENTANG DEMAND, KAPASITAS LOGISTIK TRUK, FINANSIAL, & DINAMIKA INDUSTRI LOKAL
A2: PT. MINERAL ADITIF NUSANTARA — Model Simulasi Dinamis Rentang Output (80T - 420T/Hari), 6 Skenario Lonjakan Permintaan Swasta & Megaproyek Pemerintah
A4: BAGIAN 1: MATRIKS 6 SKENARIO RENTANG DEMAND & KEBUTUHAN LOGISTIK TRUK (@ 30 TON)
A5: Kode Skenario | B5: Nama Skenario Permintaan | C5: Tipe Operasional / Shift | D5: Jam Kerja Efektif | E5: Output Harian (Ton) | F5: Output Bulanan (25 Hari) | G5: Rit Truk Outbound (@30T) | H5: Rit Dibulatkan Outbound | I5: Bentonite 80% (Ton) | J5: Rit Truk Inbound Bentonite | K5: Calsium 15% (Ton) | L5: Soda Ash 5% (Ton) | M5: Total Rit Inbound/Hari | N5: Total Lalu Lintas Truk/Hari | O5: Ketahanan Stockpile Bentonite (Jam) | P5: Buffer Holding Time Silo (Jam) | Q5: Status Risiko Logistik & Buffer
A6: SCN-01 | B6: Low Demand (Pasar Kontraksi / Retail Turun) | C6: 0.5 Shift (Setengah Hari) | D6: 4 | E6: 80 | F6: =E6*25 | G6: =E6/30 | H6: 3 | I6: =E6*0.8 | J6: =I6/30 | K6: =E6*0.15 | L6: =E6*0.05 | M6: 3 | N6: =H6+M6 | O6: =134.4/(I6/D6) | P6: =86.4/(E6/D6) | Q6: Sangat Aman (Turnover Lambat)
A7: SCN-02 | B7: Normal Baseline (Standar 1 Shift Eksisting) | C7: 1 Shift Reguler (08:30-16:30) | D7: 7 | E7: 140 | F7: =E7*25 | G7: =E7/30 | H7: 5 | I7: =E7*0.8 | J7: =I7/30 | K7: =E7*0.15 | L7: =E7*0.05 | M7: 5 | N7: =H7+M7 | O7: =134.4/(I7/D7) | P7: =86.4/(E7/D7) | Q7: Ideal & Stabil (Ekuilibrium Pabrik)
A8: SCN-03 | B8: High Commercial Surge (Lonjakan Swasta / Q2-Q3) | C8: 1 Shift + Lembur Maksimal 3 Jam | D8: 10 | E8: 200 | F8: =E8*25 | G8: =E8/30 | H8: 7 | I8: =E8*0.8 | J8: =I8/30 | K8: =E8*0.15 | L8: =E8*0.05 | M8: 7 | N8: =H8+M8 | O8: =134.4/(I8/D8) | P8: =86.4/(E8/D8) | Q8: Moderat (Wajib Jadwal Ketat Truk)
A9: SCN-04 | B9: Corporate Multiplier (Tender Swasta Besar / 2x) | C9: 2 Shift Penuh (07:00-23:00) | D9: 14 | E9: 280 | F9: =E9*25 | G9: =E9/30 | H9: 10 | I9: =E9*0.8 | J9: =I9/30 | K9: =E9*0.15 | L9: =E9*0.05 | M9: 10 | N9: =H9+M9 | O9: =134.4/(I9/D9) | P9: =86.4/(E9/D9) | Q9: Ketat (Stockpile Habis dlm 4,2 Jam)
A10: SCN-05 | B10: Massive Peak Tender (Proyek BUMN Karya / 2.5x) | C10: 2 Shift Panjang + 4 Jam Lembur | D10: 18 | E10: 360 | F10: =E10*25 | G10: =E10/30 | H10: 12 | I10: =E10*0.8 | J10: =I10/30 | K10: =E10*0.15 | L10: =E10*0.05 | M10: 13 | N10: =H10+M10 | O10: =134.4/(I10/D10) | P10: =86.4/(E10/D10) | Q10: Tinggi (Jembatan Timbang Non-Stop)
A11: SCN-06 | B11: Government Megaproject Surge (PSN / IKN 24 Jam) | C11: 3 Shift Kontinu (24 Jam Non-Stop) | D11: 21 | E11: 420 | F11: =E11*25 | G11: =E11/30 | H11: 14 | I11: =E11*0.8 | J11: =I11/30 | K11: =E11*0.15 | L11: =E11*0.05 | M11: 15 | N11: =H11+M11 | O11: =134.4/(I11/D11) | P11: =86.4/(E11/D11) | Q11: Kritis & Ekstrem (Wajib Jumbo Bag Buffer)
A13: BAGIAN 2: STRUKTUR HPP, OMZET, LABA KOTOR, DAN KEBUTUHAN MODAL KERJA CASH FLOW (TOP 30, 60, 90 HARI)
A14: Kode Skenario | B14: Output Harian | C14: Biaya Raw Material | D14: Biaya Gas PGN | E14: Biaya Listrik PLN | F14: Biaya Solar Forklift | G14: Alokasi SDM / Hari | H14: Biaya Maintenance | I14: Total Biaya Harian (HPP) | J14: HPP per Ton | K14: Harga Jual per Ton | L14: Omzet Penjualan Harian | M14: Laba Kotor Harian | N14: Gross Margin Pct | O14: Laba Kotor Bulanan (25H) | P14: Kebutuhan Modal Kerja (TOP 30H - Swasta) | Q14: Kebutuhan Modal Kerja (TOP 60H - BUMN Menengah) | R14: Kebutuhan Modal Kerja (TOP 90H - Tender Pemerintah)
A15: SCN-01 | B15: =E6 | C15: =B15*3582500 | D15: =B15*79930 | E15: =B15*7223 | F15: =B15*4738 | G15: 2675000 | H15: =B15*139006 | I15: =SUM(C15:H15) | J15: =I15/B15 | K15: 4350000 | L15: =B15*K15 | M15: =L15-I15 | N15: =M15/L15 | O15: =M15*25 | P15: =I15*30 | Q15: =I15*60 | R15: =I15*90
A16: SCN-02 | B16: =E7 | C16: =B16*3582500 | D16: =B16*79930 | E16: =B16*7223 | F16: =B16*4738 | G16: 2675000 | H16: =B16*139006 | I16: =SUM(C16:H16) | J16: =I16/B16 | K16: 4350000 | L16: =B16*K16 | M16: =L16-I16 | N16: =M16/L16 | O16: =M16*25 | P16: =I16*30 | Q16: =I16*60 | R16: =I16*90
A17: SCN-03 | B17: =E8 | C17: =B17*3582500 | D17: =B17*79930 | E17: =B17*7223 | F17: =B17*4738 | G17: 4776785 | H17: =B17*139006 | I17: =SUM(C17:H17) | J17: =I17/B17 | K17: 4350000 | L17: =B17*K17 | M17: =L17-I17 | N17: =M17/L17 | O17: =M17*25 | P17: =I17*30 | Q17: =I17*60 | R17: =I17*90
A18: SCN-04 | B18: =E9 | C18: =B18*3582500 | D18: =B18*79930 | E18: =B18*7223 | F18: =B18*4738 | G18: 5617500 | H18: =B18*139006 | I18: =SUM(C18:H18) | J18: =I18/B18 | K18: 4350000 | L18: =B18*K18 | M18: =L18-I18 | N18: =M18/L18 | O18: =M18*25 | P18: =I18*30 | Q18: =I18*60 | R18: =I18*90
A19: SCN-05 | B19: =E10 | C19: =B19*3582500 | D19: =B19*79930 | E19: =B19*7223 | F19: =B19*4738 | G19: 7720000 | H19: =B19*139006 | I19: =SUM(C19:H19) | J19: =I19/B19 | K19: 4350000 | L19: =B19*K19 | M19: =L19-I19 | N19: =M19/L19 | O19: =M19*25 | P19: =I19*30 | Q19: =I19*60 | R19: =I19*90
A20: SCN-06 | B20: =E11 | C20: =B20*3582500 | D20: =B20*79930 | E20: =B20*7223 | F20: =B20*4738 | G20: 9844000 | H20: =B20*139006 | I20: =SUM(C20:H20) | J20: =I20/B20 | K20: 4350000 | L20: =B20*K20 | M20: =L20-I20 | N20: =M20/L20 | O20: =M20*25 | P20: =I20*30 | Q20: =I20*60 | R20: =I20*90
A22: BAGIAN 3: ANALISIS DINAMIKA INDUSTRI LOKAL INDONESIA & STRATEGI MITIGASI RISIKO OPERASIONAL
A23: No | B23: Faktor Dinamika Lokal | C23: Deskripsi Kejadian Riil di Lapangan | D23: Dampak Langsung ke SCADA / Plant | E23: Sensitivitas Angka / Batasan | F23: Skenario Terdampak | G23: SOP & Strategi Mitigasi Teruji
A24: 1 | B24: Regulasi Jam Masuk Truk & Jalur Tol Arteri | C24: Pembatasan truk sumbu 3 / tronton di jalan tol & arteri pada jam sibuk (06:00-09:00 & 16:00-19:00 WIB) serta larangan angkutan barang saat libur Nataru dan Lebaran oleh Kemenhub. | D24: Truk bahan mentah tertahan di luar area industri, menyebabkan stockpile bentonite menipis mendadak di tengah produksi. | E24: Buffer stockpile bentonite (134,4 T) hanya bertahan 4,0 s.d. 8,4 jam operasional saat pabrik digeber penuh. | F24: SCN-03 s.d. SCN-06 | G24: Jadwal penerimaan inbound digeser ke malam hari (22:00 - 05:00 WIB) menggunakan sistem reservasi barcode logistik terpadu.
A25: 2 | B25: Penegakan Kebijakan Zero ODOL (Over Dimension Over Load) | C25: Penertiban jembatan timbang Kemenhub secara ketat membatasi muatan bersih truk tronton maksimal 30 Ton netto per ritase. | D25: Pabrik tidak dapat memadatkan muatan menjadi 40-45 Ton/truk. Frekuensi armada truk di jalan raya wajib meningkat drastis. | E25: Butuh 14 rit truk outbound + 15 rit inbound per hari pada Skenario 6 (Total 29 rit truk melintas di jembatan timbang internal). | F25: SCN-04, SCN-05, SCN-06 | G25: Kemitraan multi-transporter (minimal 3 konsorsium ekspedisi terverifikasi) dan standardisasi jembatan timbang internal EQ-WB-01.
A26: 3 | B26: Fluktuasi Cuaca Musim Hujan (Wet Season Tambang Open Pit) | C26: Tambang bentonite di Pulau Jawa merupakan tambang terbuka (open-pit). Saat musim hujan (Okt-Mar), kadar air (moisture) bahan mentah melonjak dari 18% ke 32-35%. | D26: Beban termal rotary dryer naik signifikan, konsumsi gas PGN naik 15-20%, serta risiko penyumbatan (choked) pada vibrating screen & conveyor. | E26: Konsumsi PGN naik dari 6,8 MMBTU/jam ke 8,2 MMBTU/jam (Tambahan beban gas ~Rp 1,5 Juta - Rp 2,2 Juta/hari). | F26: Semua Skenario (SCN-01 s.d. SCN-06) | G26: Pemasangan atap terpal kanopi ganda di Stockpile Yard 1 & 2 serta kontrol suhu burner otomatis modulasi SCADA.
A27: 4 | B27: Keterbatasan Buffer Bin Silo (72 m³ / 86,4 T) & Bottleneck Bay | C27: Bin Silo produk akhir hanya memiliki volume 72 m³. Pada kapasitas puncak 420 Ton/hari, silo penuh hanya dalam waktu 4,1 jam jika truk tangki terlambat merapat. | D27: Silo blockage high-level alarm menyala, memaksa rotary dryer dimatikan darurat (risiko bahan bakar terbuang & reheat burner Rp 17,2 - 20,5 Juta). | E27: Loading bay harus melayani 1 rit truk tangki curah (30 Ton) setiap 85 s.d. 90 menit tanpa jeda sedikit pun. | F27: SCN-04, SCN-05, SCN-06 | G27: Penerapan sistem Staging Buffer Jumbo Bag 1 Ton (PK-JMB-07) di gudang samping dengan kapasitas buffer darurat 200 Ton.
A28: 5 | B28: Term of Payment (TOP) Pengadaan Pemerintah & BUMN Karya (60-90 Hari) | C28: Proyek infrastruktur pemerintah (KemenPUPR, IKN, BUMN Karya) memiliki siklus pencairan 60 s.d. 90 hari setelah BAST dan verifikasi laboratorium terbit. | D28: Cash flow gap: Pembelian bahan baku tunai/tempo 14 hari dan tagihan gas PGN jatuh tempo tgl 20, sedangkan piutang tertahan puluhan miliar rupiah. | E28: Kebutuhan modal kerja mencapai Rp 61 Miliar (SCN-04) hingga Rp 144,1 Miliar (SCN-06) per siklus 90 hari pemesanan masif. | F28: SCN-04, SCN-05, SCN-06 | G28: Mewajibkan Down Payment (DP) tender 20-30%, memanfaatkan fasilitas perbankan Supply Chain Financing (SCF) / SKBDN, dan negosiasi tempo tambang.
A29: 6 | B29: Regulasi Ketenagakerjaan (Batas Lembur & Skema Multi-Shift) | C29: UU Cipta Kerja No. 11/2020 & PP 35/2021 membatasi kerja lembur maksimal 4 jam/hari dan 18 jam/minggu untuk melindungi K3 operator. | D29: Operasional di atas 10 jam kerja per hari TIDAK BOLEH hanya mengandalkan lembur 1 shift, melainkan WAJIB membuka Shift 2 atau Shift 3. | E29: Biaya SDM naik dari Rp 2,67 Juta/hari (1 Shift) menjadi Rp 5,61 Juta (2 Shift) dan Rp 9,84 Juta (3 Shift 4 regu rotasi). | F29: SCN-03 s.d. SCN-06 | G29: Rekrutmen tenaga kerja musiman bersertifikasi K3 dan penerapan skema roster kerja 3 shift 4 regu rotasi (siklus 6 hari kerja 2 hari off).
A30: 7 | B30: Stres Termal & Keausan Mekis Mesin Rotary Drum Dryer Kontinu | C30: Rotary Dryer berputar pada suhu 220°C. Operasional terus menerus 21 jam/hari menyebabkan keausan bearing roll dan pemuaian refractory brick furnace. | D30: Risiko breakdown fatal akibat bearing overheat jika tidak ada jeda pendinginan dan pelumasan teratur. | E30: Kehilangan output 20 Ton/jam dan biaya downtime mekanis hingga puluhan juta rupiah. | F30: SCN-05, SCN-06 | G30: Menyisakan jeda 3 jam per hari (1 jam per pergantian shift) untuk inspeksi thermal gun, re-greasing suhu tinggi, dan pembersihan filter baghouse.
A31: 8 | B31: Keterbatasan Ketersediaan Truk Ekspedisi Pihak Ketiga (3PL Deficit) | C31: Pada bulan-bulan puncak proyek konstruksi nasional, permintaan truk tronton tangki dan bak curah di pasar logistik lokal melonjak drastis. | D31: Kelangkaan armada truk sewa yang siap melayani ritase harian tepat waktu. | E31: Terjadi penumpukan produk jadi di silo pabrik dan denda penalti keterlambatan pengiriman ke lokasi proyek pemerintah. | F31: SCN-04, SCN-05, SCN-06 | G31: Menjalin kontrak eksklusif jangka panjang (Dedicated Fleet SLA) dengan 3 perusahaan logistik berbeda dengan jaminan denda penggantian armada.
A33: BAGIAN 4: SIMULASI JADWAL DISPATCH LOGISTIK PEAK DAY (TIMELINE PER JAM: 07:00 - 23:00 WIB)
A34: Jam (WIB) | B34: Status Operasional SCADA | C34: Inbound Truk Masuk (Bahan) | D34: Outbound Truk Keluar (Produk) | E34: Tonase Masuk (T) | F34: Tonase Keluar (T) | G34: Level Stockpile Bentonite (T) | H34: Level Bin Silo (T) | I34: Aktivitas Jembatan Timbang EQ-WB-01 | J34: Catatan Kontrol Logistik
A35: 07:00 - 08:00 | B35: Shift 1 Start / Preheating Burner | C35: Truk Inbound 1 (Bentonite) | D35: - | E35: 30 | F35: 0 | G35: 114.4 | H35: 30 | I35: Timbang Masuk Inbound 1 | J35: Stok awal bentonite 100T terisi truk malam
A36: 08:00 - 09:00 | B36: Produksi Aktif (20 Ton/Jam) | C36: Truk Inbound 2 (Bentonite) | D36: Truk Outbound 1 (30 Ton) | E36: 30 | F36: 30 | G36: 128.4 | H36: 20 | I36: Timbang Inbound 2 & Outbound 1 | J36: Ritme loading tangki produk pertama lancar
A37: 09:00 - 10:00 | B37: Produksi Aktif (20 Ton/Jam) | C37: Truk Inbound 3 (Calsium) | D37: - | E37: 30 | F37: 0 | G37: 112.4 | H37: 40 | I37: Timbang Inbound 3 (Calsium) | J37: Calsium dibongkar di Stockpile Bay 2
A38: 10:00 - 11:00 | B38: Produksi Aktif (20 Ton/Jam) | C38: Truk Inbound 4 (Bentonite) | D38: Truk Outbound 2 (30 Ton) | E38: 30 | F38: 30 | G38: 126.4 | H38: 30 | I38: Timbang Inbound 4 & Outbound 2 | J38: Stockpile bentonite terjaga di atas 120 Ton
A39: 11:00 - 12:00 | B39: Produksi Aktif (20 Ton/Jam) | C39: Truk Inbound 5 (Soda Ash) | D39: - | E39: 20 | F39: 0 | G39: 110.4 | H39: 50 | I39: Timbang Inbound 5 (Soda Ash) | J39: Dosing tank soda ash terisi penuh
A40: 12:00 - 13:00 | B40: Rotasi Shift / Istirahat Parsial | C40: - | D40: Truk Outbound 3 (30 Ton) | E40: 0 | F40: 30 | G40: 110.4 | H40: 20 | I40: Timbang Outbound 3 | J40: Burner low fire standby, loading bay tetap jalan
A41: 13:00 - 14:00 | B41: Produksi Aktif (20 Ton/Jam) | C41: Truk Inbound 6 (Bentonite) | D41: - | E41: 30 | F41: 0 | G41: 124.4 | H41: 40 | I41: Timbang Inbound 6 (Bentonite) | J41: Pasokan siang masuk tepat waktu
A42: 14:00 - 15:00 | B42: Produksi Aktif (20 Ton/Jam) | C42: - | D42: Truk Outbound 4 (30 Ton) | E42: 0 | F42: 30 | G42: 108.4 | H42: 30 | I42: Timbang Outbound 4 | J42: Pengiriman 120 Ton pertama tercapai
A43: 15:00 - 16:00 | B43: Shift 2 Handover / Inspeksi Mesin | C43: Truk Inbound 7 (Bentonite) | D43: - | E43: 30 | F43: 0 | G43: 122.4 | H43: 50 | I43: Timbang Inbound 7 (Bentonite) | J43: Pemeriksaan pelumasan roll bearing 15 menit
A44: 16:00 - 17:00 | B44: Produksi Aktif (20 Ton/Jam) | C44: - | D44: Truk Outbound 5 (30 Ton) | E44: 0 | F44: 30 | G44: 106.4 | H44: 40 | I44: Timbang Outbound 5 | J44: Truk tangki proyek jalan sebelum jam sibuk
...
